Workbook

Sheet Raw sheet
A1: Student_ID | B1: Age | C1: Gender | D1: Family_Income | E1: Internet_Access | F1: Study_Hours_per_Day | G1: Attendance_Rate | H1: Assignment_Delay_Days | I1: Travel_Time_Minutes | J1: Part_Time_Job | K1: Scholarship | L1: Stress_Index | M1: GPA | N1: Semester_GPA | O1: CGPA | P1: Semester | Q1: Department | R1: Parental_Education | S1: Dropout
A2: 1 | B2: 22.1 | C2: Male | D2: 25000 | E2: Yes | F2: 3.36 | G2: 86.1 | H2: 2 | I2: 20.4 | J2: Yes | K2: No | L2: 5.5 | M2: 0.96 | N2: 0.9 | O2: 0.9 | P2: Year 1 | Q2: Arts | R2: High School | S2: 0
A3: 2 | B3: 20.7 | C3: Male | D3: 25000 | E3: Yes | F3: 4.3 | G3: 68 | H3: 2 | I3: 44 | J3: No | K3: No | L3: 6.8 | M3: 1.28 | N3: 1.2 | O3: 1.19 | P3: Year 3 | Q3: Engineering | R3: Bachelor | S3: 1
A4: 3 | B4: 22.4 | C4: Male | D4: 40183 | E4: Yes | F4: 4.4 | G4: 70.9 | H4: 0 | I4: 48.9 | J4: Yes | K4: No | L4: 5.5 | M4: 1.68 | N4: 1.32 | O4: 1.32 | P4: Year 1 | Q4: Arts | R4: Master | S4: 0
A5: 4 | B5: 24.4 | C5: Male | E5: Yes | G5: 82.2 | H5: 2 | I5: 38.6 | J5: No | K5: No | M5: 1.78 | N5: 1.77 | O5: 1.77 | P5: Year 1 | Q5: CS | R5: High School | S5: 1
A6: 5 | B6: 20.5 | C6: Female | D6: 25319 | E6: Yes | F6: 4.19 | G6: 75.7 | H6: 1 | I6: 23 | J6: No | K6: No | L6: 7 | M6: 1.48 | N6: 0.91 | O6: 0.87 | P6: Year 4 | Q6: Business | R6: Bachelor | S6: 0
A7: 6 | B7: 20.5 | C7: Male | D7: 25000 | E7: Yes | F7: 4.11 | G7: 89.1 | H7: 2 | I7: 47.1 | J7: No | K7: Yes | L7: 6 | M7: 2.52 | N7: 2.72 | O7: 2.69 | P7: Year 3 | Q7: Business | R7: None | S7: 0
A8: 7 | B8: 24.5 | C8: Male | D8: 25000 | E8: Yes | F8: 3 | G8: 78.2 | H8: 1 | I8: 37.4 | J8: Yes | K8: Yes | L8: 7.3 | M8: 0.64 | N8: 0.33 | O8: 0.44 | P8: Year 4 | Q8: CS | R8: Bachelor | S8: 0
A9: 8 | B9: 22.7 | C9: Female | D9: 25000 | E9: Yes | F9: 2.12 | G9: 86.4 | H9: 1 | I9: 34 | J9: No | K9: Yes | L9: 6.5 | M9: 1.79 | N9: 1.14 | O9: 1.14 | P9: Year 1 | Q9: Arts | R9: High School | S9: 0
A10: 9 | B10: 20 | C10: Male | D10: 57413 | E10: Yes | F10: 4.07 | G10: 97.5 | H10: 3 | I10: 52.1 | J10: No | K10: No | L10: 4.2 | M10: 3.08 | N10: 2.81 | O10: 2.81 | P10: Year 1 | Q10: CS | R10: High School | S10: 0
A11: 10 | B11: 22.2 | C11: Female | D11: 44930 | E11: Yes | F11: 2.98 | G11: 82.2 | H11: 1 | I11: 19.7 | J11: No | K11: No | L11: 6.7 | M11: 1.59 | N11: 1.73 | O11: 1.73 | P11: Year 1 | Q11: Science | R11: Master | S11: 0
A12: 11 | B12: 20 | C12: Female | D12: 25000 | E12: Yes | F12: 5.27 | G12: 73.9 | H12: 3 | I12: 39.3 | J12: Yes | K12: No | L12: 7.2 | M12: 1.52 | N12: 1.5 | O12: 1.46 | P12: Year 3 | Q12: Business | R12: Bachelor | S12: 1
A13: 12 | B13: 20 | C13: Male | D13: 46056 | E13: Yes | F13: 2.37 | G13: 85.2 | H13: 6 | I13: 20.2 | J13: Yes | K13: Yes | L13: 8 | M13: 0 | N13: 0.15 | O13: 0.15 | P13: Year 2 | Q13: Engineering | R13: Bachelor | S13: 1
A14: 13 | B14: 21.5 | C14: Female | D14: 50644 | E14: Yes | F14: 3.54 | G14: 84.3 | H14: 1 | I14: 22.7 | J14: No | K14: Yes | L14: 4.6 | M14: 2.56 | N14: 2.65 | O14: 2.72 | P14: Year 4 | Q14: CS | R14: None | S14: 0
A15: 14 | B15: 17 | C15: Female | D15: 27000 | E15: Yes | F15: 4.2 | G15: 84 | H15: 1 | I15: 61.2 | J15: No | K15: Yes | L15: 4.8 | M15: 2.68 | N15: 2.7 | O15: 2.7 | P15: Year 1 | Q15: Business | R15: Bachelor | S15: 0
A16: 15 | B16: 17.2 | C16: Male | E16: Yes | G16: 92.9 | H16: 1 | I16: 36 | J16: Yes | K16: No | M16: 2.6 | N16: 2.77 | O16: 2.92 | P16: Year 3 | Q16: Engineering | R16: Bachelor | S16: 0
A17: 16 | B17: 19.8 | C17: Male | D17: 26246 | E17: No | F17: 3.49 | G17: 72.5 | H17: 2 | I17: 52.2 | J17: No | K17: No | L17: 7 | M17: 2.81 | N17: 3.15 | O17: 3.15 | P17: Year 1 | Q17: Arts | R17: Master | S17: 0
A18: 17 | B18: 18.8 | C18: Female | D18: 28037 | E18: Yes | F18: 4.24 | G18: 90 | H18: 2 | I18: 36.5 | J18: No | K18: Yes | L18: 4.6 | M18: 2.55 | N18: 2.2 | O18: 2.2 | P18: Year 1 | Q18: Engineering | R18: High School | S18: 0
A19: 18 | B19: 21.7 | C19: Female | D19: 25000 | E19: Yes | F19: 4.8 | G19: 77.2 | H19: 0 | I19: 34.8 | J19: Yes | K19: Yes | L19: 4.3 | M19: 1.99 | N19: 1.8 | O19: 1.78 | P19: Year 4 | Q19: Business | R19: Master | S19: 0
A20: 19 | B20: 19 | C20: Female | D20: 37058 | E20: Yes | F20: 4.99 | G20: 93 | H20: 2 | I20: 22.5 | J20: No | K20: No | L20: 4.7 | M20: 3.25 | N20: 3.59 | O20: 3.59 | P20: Year 1 | Q20: Arts | R20: Bachelor | S20: 0
A21: 20 | B21: 17.9 | C21: Male | D21: 35168 | E21: Yes | F21: 4.48 | G21: 65 | H21: 1 | I21: 41.7 | J21: No | K21: No | L21: 5.6 | M21: 1.71 | N21: 1.63 | O21: 1.63 | P21: Year 1 | Q21: Business | R21: Bachelor | S21: 1
A22: 21 | B22: 24.2 | C22: Female | D22: 38833 | E22: Yes | F22: 6.35 | G22: 99.8 | H22: 2 | I22: 30.3 | J22: No | K22: Yes | L22: 3.9 | M22: 2.63 | N22: 2.23 | O22: 2.23 | P22: Year 1 | Q22: CS | R22: Bachelor | S22: 0
A23: 22 | B23: 20.5 | C23: Male | D23: 35149 | E23: Yes | F23: 3.48 | G23: 79.8 | H23: 0 | I23: 31 | J23: Yes | K23: No | L23: 6.3 | M23: 2.09 | N23: 2.01 | O23: 2 | P23: Year 3 | Q23: Arts | R23: Master | S23: 0
A24: 23 | B24: 21.1 | C24: Female | D24: 46069 | E24: Yes | F24: 6.25 | G24: 72.3 | H24: 2 | I24: 26.9 | J24: Yes | K24: Yes | L24: 2.4 | M24: 4 | N24: 4 | O24: 3.92 | P24: Year 3 | Q24: CS | R24: Bachelor | S24: 0
A25: 24 | B25: 17.9 | C25: Female | D25: 26700 | E25: Yes | F25: 4.9 | G25: 89.3 | H25: 3 | I25: 28.8 | J25: No | K25: Yes | L25: 4 | M25: 3.14 | N25: 3.11 | O25: 3.04 | P25: Year 4 | Q25: Business | R25: Bachelor | S25: 0
A26: 25 | B26: 19.8 | C26: Female | D26: 33559 | E26: Yes | F26: 4.32 | G26: 86.1 | H26: 3 | I26: 30.3 | J26: Yes | K26: No | L26: 5.8 | M26: 0.42 | N26: 0.39 | O26: 0.43 | P26: Year 4 | Q26: Business | R26: PhD | S26: 1
A27: 26 | B27: 21.2 | C27: Female | D27: 25000 | E27: Yes | F27: 4.42 | G27: 85.6 | H27: 2 | I27: 31.5 | J27: No | K27: No | L27: 3.8 | M27: 3.47 | N27: 3.7 | O27: 3.66 | P27: Year 2 | Q27: CS | R27: Master | S27: 0
A28: 27 | B28: 18.5 | C28: Female | D28: 25000 | E28: Yes | F28: 5.22 | G28: 89.4 | H28: 0 | I28: 29.4 | J28: No | K28: No | L28: 4.7 | M28: 1.66 | N28: 1.77 | O28: 1.67 | P28: Year 3 | Q28: Science | R28: Bachelor | S28: 0
... A30: 29 | B30: 19.7 | C30: Male | D30: 25000 | E30: Yes | F30: 4.19 | G30: 79.7 | H30: 1 | I30: 36.5 | J30: Yes | K30: No | L30: 9.3 | M30: 1.15 | N30: 0.77 | O30: 0.76 | P30: Year 3 | Q30: Business | R30: High School | S30: 0
A31: 30 | B31: 20.4 | C31: Female | E31: No | G31: 72.7 | H31: 3 | I31: 28.5 | J31: No | K31: No | M31: 2.78 | N31: 3.03 | O31: 3.03 | P31: Year 1 | Q31: CS | R31: High School | S31: 0
A32: 31 | B32: 19.7 | C32: Female | D32: 25000 | E32: Yes | F32: 6.08 | G32: 81.1 | H32: 7 | I32: 5 | J32: Yes | K32: No | L32: 5.9 | M32: 3.96 | N32: 3.8 | O32: 3.82 | P32: Year 4 | Q32: CS | R32: Bachelor | S32: 0
A33: 32 | B33: 25.1 | C33: Male | E33: Yes | G33: 77.9 | H33: 3 | I33: 10.9 | J33: No | K33: Yes | M33: 2.56 | N33: 2.4 | O33: 2.48 | P33: Year 3 | Q33: Science | R33: Bachelor | S33: 1
A34: 33 | B34: 21 | C34: Male | D34: 34785 | E34: Yes | F34: 6.6 | G34: 81.9 | H34: 2 | I34: 24.3 | J34: No | K34: No | L34: 3.6 | M34: 3.62 | N34: 3.52 | O34: 3.53 | P34: Year 4 | Q34: Arts | R34: PhD | S34: 0
A35: 34 | B35: 18.7 | C35: Male | E35: Yes | G35: 67.9 | H35: 1 | I35: 45.3 | J35: Yes | K35: Yes | M35: 1.64 | N35: 1.69 | O35: 1.65 | P35: Year 3 | Q35: Arts | R35: Bachelor | S35: 0
A36: 35 | B36: 22.8 | C36: Female | D36: 25000 | E36: Yes | F36: 2.19 | G36: 95.9 | H36: 2 | I36: 37.3 | J36: Yes | K36: Yes | L36: 5.2 | M36: 0.76 | N36: 0.14 | O36: 0.02 | P36: Year 3 | Q36: Science | R36: Bachelor | S36: 0
A37: 36 | B37: 18.3 | C37: Female | E37: Yes | G37: 61 | H37: 1 | I37: 21.8 | J37: No | K37: Yes | M37: 0.81 | N37: 0.96 | O37: 0.97 | P37: Year 3 | Q37: Arts | R37: Bachelor | S37: 1
A38: 37 | B38: 21.5 | C38: Male | D38: 26034 | E38: No | F38: 2.9 | G38: 80.9 | H38: 1 | I38: 27.7 | J38: No | K38: Yes | L38: 7.6 | M38: 1.61 | N38: 1.41 | O38: 1.45 | P38: Year 4 | Q38: Business | R38: Bachelor | S38: 0
A39: 38 | B39: 17 | C39: Female | D39: 25000 | E39: Yes | F39: 6.16 | G39: 78.5 | H39: 0 | I39: 43.3 | J39: No | K39: No | L39: 4.7 | M39: 3.66 | N39: 3.35 | O39: 3.42 | P39: Year 2 | Q39: Science | R39: High School | S39: 0
A40: 39 | B40: 18.1 | C40: Male | D40: 77705 | E40: Yes | F40: 2.25 | G40: 70.8 | H40: 1 | I40: 22.6 | J40: No | K40: No | L40: 5 | M40: 2.16 | N40: 1.91 | O40: 2.01 | P40: Year 2 | Q40: Business | R40: None | S40: 0
A41: 40 | B41: 21.4 | C41: Female | E41: Yes | G41: 85 | H41: 3 | I41: 17 | J41: Yes | K41: No | M41: 3.1 | N41: 3.57 | O41: 3.55 | P41: Year 2 | Q41: Business | R41: Master | S41: 0
...

Sheet Student droput dataset
A1: Student_ID | B1: Age | C1: Gender | D1: Family_Income | E1: Income Level | F1: Internet_Access | G1: Study_Hours_per_Day | H1: Attendance_Rate | I1: Attendance_Status | J1: Assignment_Delay_Days | K1: Travel_Time_Minutes | L1: Part_Time_Job | M1: Scholarship | N1: Stress_Index | O1: Stress Level | P1: GPA | Q1: Semester_GPA | R1: CGPA | S1: GPA Category | T1: Semester | U1: Department | V1: Parental_Education | W1: Dropout | X1: Dropout_Status
A2: 1 | B2: 22.1 | C2: Male | D2: =IF(ISBLANK('Raw sheet'!D2),AVERAGE('Raw sheet'!$D$2:'Raw sheet'!$D$1500),'Raw sheet'!D2) -> 25000 | E2: =IF(Table1[[#This Row],[Family_Income]]>=100000,"Upper",IF(D2>=50000,"Middle","Lower")) -> Lower | F2: Yes | G2: =IF(ISBLANK('Raw sheet'!F2),AVERAGE('Raw sheet'!$F$2:'Raw sheet'!$F$1500),'Raw sheet'!F2) -> 3.36 | H2: 86.1 | I2: =IF(H2>=75,"Good","Low") -> Good | J2: 2 | K2: 20.4 | L2: Yes | M2: No | N2: =IF(ISBLANK('Raw sheet'!L2),AVERAGE('Raw sheet'!$L$2:'Raw sheet'!$L$1500),'Raw sheet'!L2) -> 5.5 | O2: =IF(Table1[[#This Row],[Stress_Index]]>=8,"High",IF(N2>=5,"Medium","Low")) -> Medium | P2: 0.96 | Q2: 0.9 | R2: 0.9 | S2: =IF(Table1[[#This Row],[CGPA]]>=3,"High",IF(R1>=2,"Medium","Low")) -> Medium | T2: Year 1 | U2: Arts | V2: High School | W2: 0 | X2: =IF(W2=1,"Dropped Out","Active") -> Active
A3: 2 | B3: 20.7 | C3: Male | D3: =IF(ISBLANK('Raw sheet'!D3),AVERAGE('Raw sheet'!$D$2:'Raw sheet'!$D$1500),'Raw sheet'!D3) -> 25000 | E3: =IF(Table1[[#This Row],[Family_Income]]>=100000,"Upper",IF(D3>=50000,"Middle","Lower")) -> Lower | F3: Yes | G3: =IF(ISBLANK('Raw sheet'!F3),AVERAGE('Raw sheet'!$F$2:'Raw sheet'!$F$1500),'Raw sheet'!F3) -> 4.3 | H3: 68 | I3: =IF(H3>=75,"Good","Low") -> Low | J3: 2 | K3: 44 | L3: No | M3: No | N3: =IF(ISBLANK('Raw sheet'!L3),AVERAGE('Raw sheet'!$L$2:'Raw sheet'!$L$1500),'Raw sheet'!L3) -> 6.8 | O3: =IF(Table1[[#This Row],[Stress_Index]]>=8,"High",IF(N3>=5,"Medium","Low")) -> Medium | P3: 1.28 | Q3: 1.2 | R3: 1.19 | S3: =IF(Table1[[#This Row],[CGPA]]>=3,"High",IF(R2>=2,"Medium","Low")) -> Low | T3: Year 3 | U3: Engineering | V3: Bachelor | W3: 1 | X3: =IF(W3=1,"Dropped Out","Active") -> Dropped Out
A4: 3 | B4: 22.4 | C4: Male | D4: =IF(ISBLANK('Raw sheet'!D4),AVERAGE('Raw sheet'!$D$2:'Raw sheet'!$D$1500),'Raw sheet'!D4) -> 40183 | E4: =IF(Table1[[#This Row],[Family_Income]]>=100000,"Upper",IF(D4>=50000,"Middle","Lower")) -> Lower | F4: Yes | G4: =IF(ISBLANK('Raw sheet'!F4),AVERAGE('Raw sheet'!$F$2:'Raw sheet'!$F$1500),'Raw sheet'!F4) -> 4.4 | H4: 70.9 | I4: =IF(H4>=75,"Good","Low") -> Low | J4: 0 | K4: 48.9 | L4: Yes | M4: No | N4: =IF(ISBLANK('Raw sheet'!L4),AVERAGE('Raw sheet'!$L$2:'Raw sheet'!$L$1500),'Raw sheet'!L4) -> 5.5 | O4: =IF(Table1[[#This Row],[Stress_Index]]>=8,"High",IF(N4>=5,"Medium","Low")) -> Medium | P4: 1.68 | Q4: 1.32 | R4: 1.32 | S4: =IF(Table1[[#This Row],[CGPA]]>=3,"High",IF(R3>=2,"Medium","Low")) -> Low | T4: Year 1 | U4: Arts | V4: Master | W4: 0 | X4: =IF(W4=1,"Dropped Out","Active") -> Active
A5: 4 | B5: 24.4 | C5: Male | D5: =IF(ISBLANK('Raw sheet'!D5),AVERAGE('Raw sheet'!$D$2:'Raw sheet'!$D$1500),'Raw sheet'!D5) -> 38587.003 | E5: =IF(Table1[[#This Row],[Family_Income]]>=100000,"Upper",IF(D5>=50000,"Middle","Lower")) -> Lower | F5: Yes | G5: =IF(ISBLANK('Raw sheet'!F5),AVERAGE('Raw sheet'!$F$2:'Raw sheet'!$F$1500),'Raw sheet'!F5) -> 4.0178702 | H5: 82.2 | I5: =IF(H5>=75,"Good","Low") -> Good | J5: 2 | K5: 38.6 | L5: No | M5: No | N5: =IF(ISBLANK('Raw sheet'!L5),AVERAGE('Raw sheet'!$L$2:'Raw sheet'!$L$1500),'Raw sheet'!L5) -> 5.5242595 | O5: =IF(Table1[[#This Row],[Stress_Index]]>=8,"High",IF(N5>=5,"Medium","Low")) -> Medium | P5: 1.78 | Q5: 1.77 | R5: 1.77 | S5: =IF(Table1[[#This Row],[CGPA]]>=3,"High",IF(R4>=2,"Medium","Low")) -> Low | T5: Year 1 | U5: CS | V5: High School | W5: 1 | X5: =IF(W5=1,"Dropped Out","Active") -> Dropped Out
A6: 5 | B6: 20.5 | C6: Female | D6: =IF(ISBLANK('Raw sheet'!D6),AVERAGE('Raw sheet'!$D$2:'Raw sheet'!$D$1500),'Raw sheet'!D6) -> 25319 | E6: =IF(Table1[[#This Row],[Family_Income]]>=100000,"Upper",IF(D6>=50000,"Middle","Lower")) -> Lower | F6: Yes | G6: =IF(ISBLANK('Raw sheet'!F6),AVERAGE('Raw sheet'!$F$2:'Raw sheet'!$F$1500),'Raw sheet'!F6) -> 4.19 | H6: 75.7 | I6: =IF(H6>=75,"Good","Low") -> Good | J6: 1 | K6: 23 | L6: No | M6: No | N6: =IF(ISBLANK('Raw sheet'!L6),AVERAGE('Raw sheet'!$L$2:'Raw sheet'!$L$1500),'Raw sheet'!L6) -> 7 | O6: =IF(Table1[[#This Row],[Stress_Index]]>=8,"High",IF(N6>=5,"Medium","Low")) -> Medium | P6: 1.48 | Q6: 0.91 | R6: 0.87 | S6: =IF(Table1[[#This Row],[CGPA]]>=3,"High",IF(R5>=2,"Medium","Low")) -> Low | T6: Year 4 | U6: Business | V6: Bachelor | W6: 0 | X6: =IF(W6=1,"Dropped Out","Active") -> Active
A7: 6 | B7: 20.5 | C7: Male | D7: =IF(ISBLANK('Raw sheet'!D7),AVERAGE('Raw sheet'!$D$2:'Raw sheet'!$D$1500),'Raw sheet'!D7) -> 25000 | E7: =IF(Table1[[#This Row],[Family_Income]]>=100000,"Upper",IF(D7>=50000,"Middle","Lower")) -> Lower | F7: Yes | G7: =IF(ISBLANK('Raw sheet'!F7),AVERAGE('Raw sheet'!$F$2:'Raw sheet'!$F$1500),'Raw sheet'!F7) -> 4.11 | H7: 89.1 | I7: =IF(H7>=75,"Good","Low") -> Good | J7: 2 | K7: 47.1 | L7: No | M7: Yes | N7: =IF(ISBLANK('Raw sheet'!L7),AVERAGE('Raw sheet'!$L$2:'Raw sheet'!$L$1500),'Raw sheet'!L7) -> 6 | O7: =IF(Table1[[#This Row],[Stress_Index]]>=8,"High",IF(N7>=5,"Medium","Low")) -> Medium | P7: 2.52 | Q7: 2.72 | R7: 2.69 | S7: =IF(Table1[[#This Row],[CGPA]]>=3,"High",IF(R6>=2,"Medium","Low")) -> Low | T7: Year 3 | U7: Business | V7: None | W7: 0 | X7: =IF(W7=1,"Dropped Out","Active") -> Active
A8: 7 | B8: 24.5 | C8: Male | D8: =IF(ISBLANK('Raw sheet'!D8),AVERAGE('Raw sheet'!$D$2:'Raw sheet'!$D$1500),'Raw sheet'!D8) -> 25000 | E8: =IF(Table1[[#This Row],[Family_Income]]>=100000,"Upper",IF(D8>=50000,"Middle","Lower")) -> Lower | F8: Yes | G8: =IF(ISBLANK('Raw sheet'!F8),AVERAGE('Raw sheet'!$F$2:'Raw sheet'!$F$1500),'Raw sheet'!F8) -> 3 | H8: 78.2 | I8: =IF(H8>=75,"Good","Low") -> Good | J8: 1 | K8: 37.4 | L8: Yes | M8: Yes | N8: =IF(ISBLANK('Raw sheet'!L8),AVERAGE('Raw sheet'!$L$2:'Raw sheet'!$L$1500),'Raw sheet'!L8) -> 7.3 | O8: =IF(Table1[[#This Row],[Stress_Index]]>=8,"High",IF(N8>=5,"Medium","Low")) -> Medium | P8: 0.64 | Q8: 0.33 | R8: 0.44 | S8: =IF(Table1[[#This Row],[CGPA]]>=3,"High",IF(R7>=2,"Medium","Low")) -> Medium | T8: Year 4 | U8: CS | V8: Bachelor | W8: 0 | X8: =IF(W8=1,"Dropped Out","Active") -> Active
A9: 8 | B9: 22.7 | C9: Female | D9: =IF(ISBLANK('Raw sheet'!D9),AVERAGE('Raw sheet'!$D$2:'Raw sheet'!$D$1500),'Raw sheet'!D9) -> 25000 | E9: =IF(Table1[[#This Row],[Family_Income]]>=100000,"Upper",IF(D9>=50000,"Middle","Lower")) -> Lower | F9: Yes | G9: =IF(ISBLANK('Raw sheet'!F9),AVERAGE('Raw sheet'!$F$2:'Raw sheet'!$F$1500),'Raw sheet'!F9) -> 2.12 | H9: 86.4 | I9: =IF(H9>=75,"Good","Low") -> Good | J9: 1 | K9: 34 | L9: No | M9: Yes | N9: =IF(ISBLANK('Raw sheet'!L9),AVERAGE('Raw sheet'!$L$2:'Raw sheet'!$L$1500),'Raw sheet'!L9) -> 6.5 | O9: =IF(Table1[[#This Row],[Stress_Index]]>=8,"High",IF(N9>=5,"Medium","Low")) -> Medium | P9: 1.79 | Q9: 1.14 | R9: 1.14 | S9: =IF(Table1[[#This Row],[CGPA]]>=3,"High",IF(R8>=2,"Medium","Low")) -> Low | T9: Year 1 | U9: Arts | V9: High School | W9: 0 | X9: =IF(W9=1,"Dropped Out","Active") -> Active
A10: 9 | B10: 20 | C10: Male | D10: =IF(ISBLANK('Raw sheet'!D10),AVERAGE('Raw sheet'!$D$2:'Raw sheet'!$D$1500),'Raw sheet'!D10) -> 57413 | E10: =IF(Table1[[#This Row],[Family_Income]]>=100000,"Upper",IF(D10>=50000,"Middle","Lower")) -> Middle | F10: Yes | G10: =IF(ISBLANK('Raw sheet'!F10),AVERAGE('Raw sheet'!$F$2:'Raw sheet'!$F$1500),'Raw sheet'!F10) -> 4.07 | H10: 97.5 | I10: =IF(H10>=75,"Good","Low") -> Good | J10: 3 | K10: 52.1 | L10: No | M10: No | N10: =IF(ISBLANK('Raw sheet'!L10),AVERAGE('Raw sheet'!$L$2:'Raw sheet'!$L$1500),'Raw sheet'!L10) -> 4.2 | O10: =IF(Table1[[#This Row],[Stress_Index]]>=8,"High",IF(N10>=5,"Medium","Low")) -> Low | P10: 3.08 | Q10: 2.81 | R10: 2.81 | S10: =IF(Table1[[#This Row],[CGPA]]>=3,"High",IF(R9>=2,"Medium","Low")) -> Low | T10: Year 1 | U10: CS | V10: High School | W10: 0 | X10: =IF(W10=1,"Dropped Out","Active") -> Active
A11: 10 | B11: 22.2 | C11: Female | D11: =IF(ISBLANK('Raw sheet'!D11),AVERAGE('Raw sheet'!$D$2:'Raw sheet'!$D$1500),'Raw sheet'!D11) -> 44930 | E11: =IF(Table1[[#This Row],[Family_Income]]>=100000,"Upper",IF(D11>=50000,"Middle","Lower")) -> Lower | F11: Yes | G11: =IF(ISBLANK('Raw sheet'!F11),AVERAGE('Raw sheet'!$F$2:'Raw sheet'!$F$1500),'Raw sheet'!F11) -> 2.98 | H11: 82.2 | I11: =IF(H11>=75,"Good","Low") -> Good | J11: 1 | K11: 19.7 | L11: No | M11: No | N11: =IF(ISBLANK('Raw sheet'!L11),AVERAGE('Raw sheet'!$L$2:'Raw sheet'!$L$1500),'Raw sheet'!L11) -> 6.7 | O11: =IF(Table1[[#This Row],[Stress_Index]]>=8,"High",IF(N11>=5,"Medium","Low")) -> Medium | P11: 1.59 | Q11: 1.73 | R11: 1.73 | S11: =IF(Table1[[#This Row],[CGPA]]>=3,"High",IF(R10>=2,"Medium","Low")) -> Medium | T11: Year 1 | U11: Science | V11: Master | W11: 0 | X11: =IF(W11=1,"Dropped Out","Active") -> Active
A12: 11 | B12: 20 | C12: Female | D12: =IF(ISBLANK('Raw sheet'!D12),AVERAGE('Raw sheet'!$D$2:'Raw sheet'!$D$1500),'Raw sheet'!D12) -> 25000 | E12: =IF(Table1[[#This Row],[Family_Income]]>=100000,"Upper",IF(D12>=50000,"Middle","Lower")) -> Lower | F12: Yes | G12: =IF(ISBLANK('Raw sheet'!F12),AVERAGE('Raw sheet'!$F$2:'Raw sheet'!$F$1500),'Raw sheet'!F12) -> 5.27 | H12: 73.9 | I12: =IF(H12>=75,"Good","Low") -> Low | J12: 3 | K12: 39.3 | L12: Yes | M12: No | N12: =IF(ISBLANK('Raw sheet'!L12),AVERAGE('Raw sheet'!$L$2:'Raw sheet'!$L$1500),'Raw sheet'!L12) -> 7.2 | O12: =IF(Table1[[#This Row],[Stress_Index]]>=8,"High",IF(N12>=5,"Medium","Low")) -> Medium | P12: 1.52 | Q12: 1.5 | R12: 1.46 | S12: =IF(Table1[[#This Row],[CGPA]]>=3,"High",IF(R11>=2,"Medium","Low")) -> Low | T12: Year 3 | U12: Business | V12: Bachelor | W12: 1 | X12: =IF(W12=1,"Dropped Out","Active") -> Dropped Out
A13: 12 | B13: 20 | C13: Male | D13: =IF(ISBLANK('Raw sheet'!D13),AVERAGE('Raw sheet'!$D$2:'Raw sheet'!$D$1500),'Raw sheet'!D13) -> 46056 | E13: =IF(Table1[[#This Row],[Family_Income]]>=100000,"Upper",IF(D13>=50000,"Middle","Lower")) -> Lower | F13: Yes | G13: =IF(ISBLANK('Raw sheet'!F13),AVERAGE('Raw sheet'!$F$2:'Raw sheet'!$F$1500),'Raw sheet'!F13) -> 2.37 | H13: 85.2 | I13: =IF(H13>=75,"Good","Low") -> Good | J13: 6 | K13: 20.2 | L13: Yes | M13: Yes | N13: =IF(ISBLANK('Raw sheet'!L13),AVERAGE('Raw sheet'!$L$2:'Raw sheet'!$L$1500),'Raw sheet'!L13) -> 8 | O13: =IF(Table1[[#This Row],[Stress_Index]]>=8,"High",IF(N13>=5,"Medium","Low")) -> High | P13: 0 | Q13: 0.15 | R13: 0.15 | S13: =IF(Table1[[#This Row],[CGPA]]>=3,"High",IF(R12>=2,"Medium","Low")) -> Low | T13: Year 2 | U13: Engineering | V13: Bachelor | W13: 1 | X13: =IF(W13=1,"Dropped Out","Active") -> Dropped Out
... A1500: 1499 | B1500: 23.3 | C1500: Male | D1500: =IF(ISBLANK('Raw sheet'!D1500),AVERAGE('Raw sheet'!$D$2:'Raw sheet'!$D$1500),'Raw sheet'!D1500) -> 38587.003 | E1500: =IF(Table1[[#This Row],[Family_Income]]>=100000,"Upper",IF(D1500>=50000,"Middle","Lower")) -> Lower | F1500: Yes | G1500: =IF(ISBLANK('Raw sheet'!F1500),AVERAGE('Raw sheet'!$F$2:'Raw sheet'!$F$1500),'Raw sheet'!F1500) -> 4.0178702 | H1500: 95.9 | I1500: =IF(H1500>=75,"Good","Low") -> Good | J1500: 1 | K1500: 7 | L1500: Yes | M1500: No | N1500: =IF(ISBLANK('Raw sheet'!L1500),AVERAGE('Raw sheet'!$L$2:'Raw sheet'!$L$1500),'Raw sheet'!L1500) -> 5.5242595 | O1500: =IF(Table1[[#This Row],[Stress_Index]]>=8,"High",IF(N1500>=5,"Medium","Low")) -> Medium | P1500: 2.66 | Q1500: 2.79 | R1500: 2.79 | S1500: =IF(Table1[[#This Row],[CGPA]]>=3,"High",IF(R1499>=2,"Medium","Low")) -> Low | T1500: Year 1 | U1500: Arts | V1500: Master | W1500: 0 | X1500: =IF(W1500=1,"Dropped Out","Active") -> Active
